<?xml version="1.0" ?>
<robot name="ros" xmlns:xacro="http://www.ros.org/wiki/xacro">

<xacro:include filename="$(find robot)/urdf/materials.xacro" />
<xacro:include filename="$(find robot)/urdf/properties.xacro" />

<link name="base_link">
  <inertial>
    <origin xyz="-0.0004442275486858486 -0.027763800307559608 0.04075489489760404" rpy="0 0 0"/>
    <mass value="1.449043338359083"/>
    <inertia ixx="0.012" iyy="0.013382" izz="0.01271" ixy="0.0" iyz="-0.000167" ixz="0.0"/>
  </inertial>
  <visual>
    <origin xyz="0 0 0" rpy="0 0 0"/>
    <geometry>
      <mesh filename="file://$(find robot)/meshes/base_link.stl" scale="0.001 0.001 0.001"/>
    </geometry>
    <material name="silver"/>
  </visual>
  <collision>
    <origin xyz="0 0 0" rpy="0 0 0"/>
    <geometry>
      <mesh filename="file://$(find robot)/meshes/base_link.stl" scale="0.001 0.001 0.001"/>
    </geometry>
  </collision>
</link>

<link name="right_wheel_1">
  <inertial>
    <origin xyz="-0.027427780444362282 -2.029127972526094e-06 1.7824236945435112e-07" rpy="0 0 0"/>
    <mass value="0.05590599422944014"/>
    <inertia ixx="5e-05" iyy="3.2e-05" izz="3.2e-05" ixy="0.0" iyz="-0.0" ixz="-0.0"/>
  </inertial>
  <visual>
    <origin xyz="0.124245 -0.000899 0.037546" rpy="0 0 0"/>
    <geometry>
      <mesh filename="file://$(find robot)/meshes/right_wheel_1.stl" scale="0.001 0.001 0.001"/>
    </geometry>
    <material name="silver"/>
  </visual>
  <collision>
    <origin xyz="0.124245 -0.000899 0.037546" rpy="0 0 0"/>
    <geometry>
      <mesh filename="file://$(find robot)/meshes/right_wheel_1.stl" scale="0.001 0.001 0.001"/>
    </geometry>
  </collision>
</link>

<link name="left_wheel_1">
  <inertial>
    <origin xyz="0.027427493070124417 -2.0291279724919415e-06 1.5656025283833364e-07" rpy="0 0 0"/>
    <mass value="0.05590599422944014"/>
    <inertia ixx="5e-05" iyy="3.2e-05" izz="3.2e-05" ixy="-0.0" iyz="0.0" ixz="-0.0"/>
  </inertial>
  <visual>
    <origin xyz="-0.123355 -0.000899 0.037546" rpy="0 0 0"/>
    <geometry>
      <mesh filename="file://$(find robot)/meshes/left_wheel_1.stl" scale="0.001 0.001 0.001"/>
    </geometry>
    <material name="silver"/>
  </visual>
  <collision>
    <origin xyz="-0.123355 -0.000899 0.037546" rpy="0 0 0"/>
    <geometry>
      <mesh filename="file://$(find robot)/meshes/left_wheel_1.stl" scale="0.001 0.001 0.001"/>
    </geometry>
  </collision>
</link>

<joint name="right_wheel_joint" type="continuous">
  <origin xyz="-0.124245 0.000899 -0.037546" rpy="0 0 0"/>
  <parent link="base_link"/>
  <child link="right_wheel_1"/>
  <axis xyz="-1.0 -0.0 -0.0"/>
</joint>

<joint name="left_wheel_joint" type="continuous">
  <origin xyz="0.123355 0.000899 -0.037546" rpy="0 0 0"/>
  <parent link="base_link"/>
  <child link="left_wheel_1"/>
  <axis xyz="1.0 -0.0 -0.0"/>
</joint>

</robot>
 